[2023-04-15T06:50:17.276+0000] {taskinstance.py:1084} INFO - Dependencies all met for dep_context=non-requeueable deps ti=<TaskInstance: tutorial_executa_dag.capture_count_data scheduled__2023-04-15T05:30:00+00:00 [queued]>
[2023-04-15T06:50:17.303+0000] {taskinstance.py:1084} INFO - Dependencies all met for dep_context=requeueable deps ti=<TaskInstance: tutorial_executa_dag.capture_count_data scheduled__2023-04-15T05:30:00+00:00 [queued]>
[2023-04-15T06:50:17.307+0000] {taskinstance.py:1282} INFO - 
--------------------------------------------------------------------------------
[2023-04-15T06:50:17.313+0000] {taskinstance.py:1283} INFO - Starting attempt 1 of 1
[2023-04-15T06:50:17.316+0000] {taskinstance.py:1284} INFO - 
--------------------------------------------------------------------------------
[2023-04-15T06:50:17.356+0000] {taskinstance.py:1303} INFO - Executing <Task(PythonOperator): capture_count_data> on 2023-04-15 05:30:00+00:00
[2023-04-15T06:50:17.363+0000] {standard_task_runner.py:55} INFO - Started process 630 to run task
[2023-04-15T06:50:17.370+0000] {standard_task_runner.py:82} INFO - Running: ['***', 'tasks', 'run', 'tutorial_executa_dag', 'capture_count_data', 'scheduled__2023-04-15T05:30:00+00:00', '--job-id', '94', '--raw', '--subdir', 'DAGS_FOLDER/tutorial_executa_dag.py', '--cfg-path', '/tmp/tmpb0k3i4vx']
[2023-04-15T06:50:17.376+0000] {standard_task_runner.py:83} INFO - Job 94: Subtask capture_count_data
[2023-04-15T06:50:17.686+0000] {task_command.py:388} INFO - Running <TaskInstance: tutorial_executa_dag.capture_count_data scheduled__2023-04-15T05:30:00+00:00 [running]> on host 229ecb906897
[2023-04-15T06:50:17.834+0000] {taskinstance.py:1511} INFO - Exporting the following env vars:
AIRFLOW_CTX_DAG_OWNER=***
AIRFLOW_CTX_DAG_ID=tutorial_executa_dag
AIRFLOW_CTX_TASK_ID=capture_count_data
AIRFLOW_CTX_EXECUTION_DATE=2023-04-15T05:30:00+00:00
AIRFLOW_CTX_TRY_NUMBER=1
AIRFLOW_CTX_DAG_RUN_ID=scheduled__2023-04-15T05:30:00+00:00
[2023-04-15T06:50:34.520+0000] {taskinstance.py:1775} ERROR - Task failed with exception
Traceback (most recent call last):
  File "/home/airflow/.local/lib/python3.7/site-packages/urllib3/response.py", line 444, in _error_catcher
    yield
  File "/home/airflow/.local/lib/python3.7/site-packages/urllib3/response.py", line 831, in read_chunked
    chunk = self._handle_chunk(amt)
  File "/home/airflow/.local/lib/python3.7/site-packages/urllib3/response.py", line 784, in _handle_chunk
    returned_chunk = self._fp._safe_read(self.chunk_left)
  File "/usr/local/lib/python3.7/http/client.py", line 630, in _safe_read
    raise IncompleteRead(b''.join(s), amt)
http.client.IncompleteRead: IncompleteRead(5978 bytes read, 166 more expected)

During handling of the above exception, another exception occurred:

Traceback (most recent call last):
  File "/home/airflow/.local/lib/python3.7/site-packages/requests/models.py", line 816, in generate
    yield from self.raw.stream(chunk_size, decode_content=True)
  File "/home/airflow/.local/lib/python3.7/site-packages/urllib3/response.py", line 624, in stream
    for line in self.read_chunked(amt, decode_content=decode_content):
  File "/home/airflow/.local/lib/python3.7/site-packages/urllib3/response.py", line 857, in read_chunked
    self._original_response.close()
  File "/usr/local/lib/python3.7/contextlib.py", line 130, in __exit__
    self.gen.throw(type, value, traceback)
  File "/home/airflow/.local/lib/python3.7/site-packages/urllib3/response.py", line 461, in _error_catcher
    raise ProtocolError("Connection broken: %r" % e, e)
urllib3.exceptions.ProtocolError: ('Connection broken: IncompleteRead(5978 bytes read, 166 more expected)', IncompleteRead(5978 bytes read, 166 more expected))

During handling of the above exception, another exception occurred:

Traceback (most recent call last):
  File "/home/airflow/.local/lib/python3.7/site-packages/airflow/operators/python.py", line 175, in execute
    return_value = self.execute_callable()
  File "/home/airflow/.local/lib/python3.7/site-packages/airflow/operators/python.py", line 192, in execute_callable
    return self.python_callable(*self.op_args, **self.op_kwargs)
  File "/opt/airflow/dags/tutorial_executa_dag.py", line 28, in handle_capture_count_data
    response = requests.get(url)
  File "/home/airflow/.local/lib/python3.7/site-packages/requests/api.py", line 73, in get
    return request("get", url, params=params, **kwargs)
  File "/home/airflow/.local/lib/python3.7/site-packages/requests/api.py", line 59, in request
    return session.request(method=method, url=url, **kwargs)
  File "/home/airflow/.local/lib/python3.7/site-packages/requests/sessions.py", line 587, in request
    resp = self.send(prep, **send_kwargs)
  File "/home/airflow/.local/lib/python3.7/site-packages/requests/sessions.py", line 745, in send
    r.content
  File "/home/airflow/.local/lib/python3.7/site-packages/requests/models.py", line 899, in content
    self._content = b"".join(self.iter_content(CONTENT_CHUNK_SIZE)) or b""
  File "/home/airflow/.local/lib/python3.7/site-packages/requests/models.py", line 818, in generate
    raise ChunkedEncodingError(e)
requests.exceptions.ChunkedEncodingError: ('Connection broken: IncompleteRead(5978 bytes read, 166 more expected)', IncompleteRead(5978 bytes read, 166 more expected))
[2023-04-15T06:50:34.606+0000] {taskinstance.py:1326} INFO - Marking task as FAILED. dag_id=tutorial_executa_dag, task_id=capture_count_data, execution_date=20230415T053000, start_date=20230415T065017, end_date=20230415T065034
[2023-04-15T06:50:34.690+0000] {standard_task_runner.py:105} ERROR - Failed to execute job 94 for task capture_count_data (('Connection broken: IncompleteRead(5978 bytes read, 166 more expected)', IncompleteRead(5978 bytes read, 166 more expected)); 630)
[2023-04-15T06:50:34.831+0000] {local_task_job.py:212} INFO - Task exited with return code 1
[2023-04-15T06:50:34.992+0000] {taskinstance.py:2585} INFO - 0 downstream tasks scheduled from follow-on schedule check
