[2023-04-16T14:26:31.674+0000] {taskinstance.py:1084} INFO - Dependencies all met for dep_context=non-requeueable deps ti=<TaskInstance: preparo_receita.formatar_receita manual__2023-04-16T14:26:29.834442+00:00 [queued]>
[2023-04-16T14:26:31.680+0000] {taskinstance.py:1084} INFO - Dependencies all met for dep_context=requeueable deps ti=<TaskInstance: preparo_receita.formatar_receita manual__2023-04-16T14:26:29.834442+00:00 [queued]>
[2023-04-16T14:26:31.681+0000] {taskinstance.py:1282} INFO - 
--------------------------------------------------------------------------------
[2023-04-16T14:26:31.681+0000] {taskinstance.py:1283} INFO - Starting attempt 1 of 1
[2023-04-16T14:26:31.682+0000] {taskinstance.py:1284} INFO - 
--------------------------------------------------------------------------------
[2023-04-16T14:26:31.696+0000] {taskinstance.py:1303} INFO - Executing <Task(PythonOperator): formatar_receita> on 2023-04-16 14:26:29.834442+00:00
[2023-04-16T14:26:31.707+0000] {standard_task_runner.py:55} INFO - Started process 52 to run task
[2023-04-16T14:26:31.712+0000] {standard_task_runner.py:82} INFO - Running: ['***', 'tasks', 'run', 'preparo_receita', 'formatar_receita', 'manual__2023-04-16T14:26:29.834442+00:00', '--job-id', '152', '--raw', '--subdir', 'DAGS_FOLDER/preparo_receita_dag.py', '--cfg-path', '/tmp/tmp8lla0jeq']
[2023-04-16T14:26:31.713+0000] {standard_task_runner.py:83} INFO - Job 152: Subtask formatar_receita
[2023-04-16T14:26:31.789+0000] {task_command.py:388} INFO - Running <TaskInstance: preparo_receita.formatar_receita manual__2023-04-16T14:26:29.834442+00:00 [running]> on host 74f80fb1551d
[2023-04-16T14:26:31.852+0000] {taskinstance.py:1511} INFO - Exporting the following env vars:
AIRFLOW_CTX_DAG_OWNER=***
AIRFLOW_CTX_DAG_ID=preparo_receita
AIRFLOW_CTX_TASK_ID=formatar_receita
AIRFLOW_CTX_EXECUTION_DATE=2023-04-16T14:26:29.834442+00:00
AIRFLOW_CTX_TRY_NUMBER=1
AIRFLOW_CTX_DAG_RUN_ID=manual__2023-04-16T14:26:29.834442+00:00
[2023-04-16T14:26:31.854+0000] {taskinstance.py:1775} ERROR - Task failed with exception
Traceback (most recent call last):
  File "/home/airflow/.local/lib/python3.7/site-packages/airflow/operators/python.py", line 175, in execute
    return_value = self.execute_callable()
  File "/home/airflow/.local/lib/python3.7/site-packages/airflow/operators/python.py", line 192, in execute_callable
    return self.python_callable(*self.op_args, **self.op_kwargs)
  File "/opt/airflow/dags/preparo_receita_dag.py", line 28, in formatar_receita
    with open('receita.json', 'r') as f:
FileNotFoundError: [Errno 2] No such file or directory: 'receita.json'
[2023-04-16T14:26:31.863+0000] {taskinstance.py:1326} INFO - Marking task as FAILED. dag_id=preparo_receita, task_id=formatar_receita, execution_date=20230416T142629, start_date=20230416T142631, end_date=20230416T142631
[2023-04-16T14:26:31.874+0000] {standard_task_runner.py:105} ERROR - Failed to execute job 152 for task formatar_receita ([Errno 2] No such file or directory: 'receita.json'; 52)
[2023-04-16T14:26:31.885+0000] {local_task_job.py:212} INFO - Task exited with return code 1
[2023-04-16T14:26:31.917+0000] {taskinstance.py:2585} INFO - 0 downstream tasks scheduled from follow-on schedule check
