[2023-04-16T14:33:32.444+0000] {taskinstance.py:1084} INFO - Dependencies all met for dep_context=non-requeueable deps ti=<TaskInstance: preparo_receita.verificar_tempo_preparo manual__2023-04-16T14:33:30.023383+00:00 [queued]>
[2023-04-16T14:33:32.471+0000] {taskinstance.py:1084} INFO - Dependencies all met for dep_context=requeueable deps ti=<TaskInstance: preparo_receita.verificar_tempo_preparo manual__2023-04-16T14:33:30.023383+00:00 [queued]>
[2023-04-16T14:33:32.473+0000] {taskinstance.py:1282} INFO - 
--------------------------------------------------------------------------------
[2023-04-16T14:33:32.474+0000] {taskinstance.py:1283} INFO - Starting attempt 1 of 1
[2023-04-16T14:33:32.475+0000] {taskinstance.py:1284} INFO - 
--------------------------------------------------------------------------------
[2023-04-16T14:33:32.509+0000] {taskinstance.py:1303} INFO - Executing <Task(PythonOperator): verificar_tempo_preparo> on 2023-04-16 14:33:30.023383+00:00
[2023-04-16T14:33:32.517+0000] {standard_task_runner.py:55} INFO - Started process 62 to run task
[2023-04-16T14:33:32.524+0000] {standard_task_runner.py:82} INFO - Running: ['***', 'tasks', 'run', 'preparo_receita', 'verificar_tempo_preparo', 'manual__2023-04-16T14:33:30.023383+00:00', '--job-id', '159', '--raw', '--subdir', 'DAGS_FOLDER/preparo_receita_dag.py', '--cfg-path', '/tmp/tmp__zzcp86']
[2023-04-16T14:33:32.543+0000] {standard_task_runner.py:83} INFO - Job 159: Subtask verificar_tempo_preparo
[2023-04-16T14:33:32.684+0000] {task_command.py:388} INFO - Running <TaskInstance: preparo_receita.verificar_tempo_preparo manual__2023-04-16T14:33:30.023383+00:00 [running]> on host 74f80fb1551d
[2023-04-16T14:33:32.809+0000] {taskinstance.py:1511} INFO - Exporting the following env vars:
AIRFLOW_CTX_DAG_OWNER=***
AIRFLOW_CTX_DAG_ID=preparo_receita
AIRFLOW_CTX_TASK_ID=verificar_tempo_preparo
AIRFLOW_CTX_EXECUTION_DATE=2023-04-16T14:33:30.023383+00:00
AIRFLOW_CTX_TRY_NUMBER=1
AIRFLOW_CTX_DAG_RUN_ID=manual__2023-04-16T14:33:30.023383+00:00
[2023-04-16T14:33:32.811+0000] {taskinstance.py:1775} ERROR - Task failed with exception
Traceback (most recent call last):
  File "/home/airflow/.local/lib/python3.7/site-packages/airflow/operators/python.py", line 175, in execute
    return_value = self.execute_callable()
  File "/home/airflow/.local/lib/python3.7/site-packages/airflow/operators/python.py", line 192, in execute_callable
    return self.python_callable(*self.op_args, **self.op_kwargs)
  File "/opt/airflow/dags/preparo_receita_dag.py", line 8, in verificar_tempo_preparo
    with open('./receita.json', 'r') as f:
FileNotFoundError: [Errno 2] No such file or directory: './receita.json'
[2023-04-16T14:33:32.842+0000] {taskinstance.py:1326} INFO - Marking task as FAILED. dag_id=preparo_receita, task_id=verificar_tempo_preparo, execution_date=20230416T143330, start_date=20230416T143332, end_date=20230416T143332
[2023-04-16T14:33:32.871+0000] {standard_task_runner.py:105} ERROR - Failed to execute job 159 for task verificar_tempo_preparo ([Errno 2] No such file or directory: './receita.json'; 62)
[2023-04-16T14:33:32.907+0000] {local_task_job.py:212} INFO - Task exited with return code 1
[2023-04-16T14:33:32.948+0000] {taskinstance.py:2585} INFO - 0 downstream tasks scheduled from follow-on schedule check
