[2023-04-15T05:46:10.495+0000] {taskinstance.py:1084} INFO - Dependencies all met for dep_context=non-requeueable deps ti=<TaskInstance: tutorial_executa_dag.capture_count_data scheduled__2023-04-15T04:30:00+00:00 [queued]>
[2023-04-15T05:46:10.509+0000] {taskinstance.py:1084} INFO - Dependencies all met for dep_context=requeueable deps ti=<TaskInstance: tutorial_executa_dag.capture_count_data scheduled__2023-04-15T04:30:00+00:00 [queued]>
[2023-04-15T05:46:10.510+0000] {taskinstance.py:1282} INFO - 
--------------------------------------------------------------------------------
[2023-04-15T05:46:10.510+0000] {taskinstance.py:1283} INFO - Starting attempt 1 of 1
[2023-04-15T05:46:10.510+0000] {taskinstance.py:1284} INFO - 
--------------------------------------------------------------------------------
[2023-04-15T05:46:10.523+0000] {taskinstance.py:1303} INFO - Executing <Task(PythonOperator): capture_count_data> on 2023-04-15 04:30:00+00:00
[2023-04-15T05:46:10.529+0000] {standard_task_runner.py:55} INFO - Started process 611 to run task
[2023-04-15T05:46:10.580+0000] {standard_task_runner.py:82} INFO - Running: ['***', 'tasks', 'run', 'tutorial_executa_dag', 'capture_count_data', 'scheduled__2023-04-15T04:30:00+00:00', '--job-id', '92', '--raw', '--subdir', 'DAGS_FOLDER/tutorial_executa_dag.py', '--cfg-path', '/tmp/tmp5tluc6xo']
[2023-04-15T05:46:10.586+0000] {standard_task_runner.py:83} INFO - Job 92: Subtask capture_count_data
[2023-04-15T05:46:10.724+0000] {task_command.py:388} INFO - Running <TaskInstance: tutorial_executa_dag.capture_count_data scheduled__2023-04-15T04:30:00+00:00 [running]> on host 229ecb906897
[2023-04-15T05:46:10.797+0000] {taskinstance.py:1511} INFO - Exporting the following env vars:
AIRFLOW_CTX_DAG_OWNER=***
AIRFLOW_CTX_DAG_ID=tutorial_executa_dag
AIRFLOW_CTX_TASK_ID=capture_count_data
AIRFLOW_CTX_EXECUTION_DATE=2023-04-15T04:30:00+00:00
AIRFLOW_CTX_TRY_NUMBER=1
AIRFLOW_CTX_DAG_RUN_ID=scheduled__2023-04-15T04:30:00+00:00
[2023-04-15T05:46:27.306+0000] {taskinstance.py:1775} ERROR - Task failed with exception
Traceback (most recent call last):
  File "/home/airflow/.local/lib/python3.7/site-packages/urllib3/connectionpool.py", line 710, in urlopen
    chunked=chunked,
  File "/home/airflow/.local/lib/python3.7/site-packages/urllib3/connectionpool.py", line 449, in _make_request
    six.raise_from(e, None)
  File "<string>", line 3, in raise_from
  File "/home/airflow/.local/lib/python3.7/site-packages/urllib3/connectionpool.py", line 444, in _make_request
    httplib_response = conn.getresponse()
  File "/usr/local/lib/python3.7/http/client.py", line 1373, in getresponse
    response.begin()
  File "/usr/local/lib/python3.7/http/client.py", line 319, in begin
    version, status, reason = self._read_status()
  File "/usr/local/lib/python3.7/http/client.py", line 288, in _read_status
    raise RemoteDisconnected("Remote end closed connection without"
http.client.RemoteDisconnected: Remote end closed connection without response

During handling of the above exception, another exception occurred:

Traceback (most recent call last):
  File "/home/airflow/.local/lib/python3.7/site-packages/requests/adapters.py", line 499, in send
    timeout=timeout,
  File "/home/airflow/.local/lib/python3.7/site-packages/urllib3/connectionpool.py", line 788, in urlopen
    method, url, error=e, _pool=self, _stacktrace=sys.exc_info()[2]
  File "/home/airflow/.local/lib/python3.7/site-packages/urllib3/util/retry.py", line 550, in increment
    raise six.reraise(type(error), error, _stacktrace)
  File "/home/airflow/.local/lib/python3.7/site-packages/urllib3/packages/six.py", line 769, in reraise
    raise value.with_traceback(tb)
  File "/home/airflow/.local/lib/python3.7/site-packages/urllib3/connectionpool.py", line 710, in urlopen
    chunked=chunked,
  File "/home/airflow/.local/lib/python3.7/site-packages/urllib3/connectionpool.py", line 449, in _make_request
    six.raise_from(e, None)
  File "<string>", line 3, in raise_from
  File "/home/airflow/.local/lib/python3.7/site-packages/urllib3/connectionpool.py", line 444, in _make_request
    httplib_response = conn.getresponse()
  File "/usr/local/lib/python3.7/http/client.py", line 1373, in getresponse
    response.begin()
  File "/usr/local/lib/python3.7/http/client.py", line 319, in begin
    version, status, reason = self._read_status()
  File "/usr/local/lib/python3.7/http/client.py", line 288, in _read_status
    raise RemoteDisconnected("Remote end closed connection without"
urllib3.exceptions.ProtocolError: ('Connection aborted.', RemoteDisconnected('Remote end closed connection without response'))

During handling of the above exception, another exception occurred:

Traceback (most recent call last):
  File "/home/airflow/.local/lib/python3.7/site-packages/airflow/operators/python.py", line 175, in execute
    return_value = self.execute_callable()
  File "/home/airflow/.local/lib/python3.7/site-packages/airflow/operators/python.py", line 192, in execute_callable
    return self.python_callable(*self.op_args, **self.op_kwargs)
  File "/opt/airflow/dags/tutorial_executa_dag.py", line 28, in handle_capture_count_data
    response = requests.get(url)
  File "/home/airflow/.local/lib/python3.7/site-packages/requests/api.py", line 73, in get
    return request("get", url, params=params, **kwargs)
  File "/home/airflow/.local/lib/python3.7/site-packages/requests/api.py", line 59, in request
    return session.request(method=method, url=url, **kwargs)
  File "/home/airflow/.local/lib/python3.7/site-packages/requests/sessions.py", line 587, in request
    resp = self.send(prep, **send_kwargs)
  File "/home/airflow/.local/lib/python3.7/site-packages/requests/sessions.py", line 701, in send
    r = adapter.send(request, **kwargs)
  File "/home/airflow/.local/lib/python3.7/site-packages/requests/adapters.py", line 547, in send
    raise ConnectionError(err, request=request)
requests.exceptions.ConnectionError: ('Connection aborted.', RemoteDisconnected('Remote end closed connection without response'))
[2023-04-15T05:46:27.371+0000] {taskinstance.py:1326} INFO - Marking task as FAILED. dag_id=tutorial_executa_dag, task_id=capture_count_data, execution_date=20230415T043000, start_date=20230415T054610, end_date=20230415T054627
[2023-04-15T05:46:27.417+0000] {standard_task_runner.py:105} ERROR - Failed to execute job 92 for task capture_count_data (('Connection aborted.', RemoteDisconnected('Remote end closed connection without response')); 611)
[2023-04-15T05:46:27.484+0000] {local_task_job.py:212} INFO - Task exited with return code 1
[2023-04-15T05:46:27.532+0000] {taskinstance.py:2585} INFO - 0 downstream tasks scheduled from follow-on schedule check
